<?xml version="1.0" encoding="UTF-8"?>
<testng-results skipped="0" failed="3" ignored="0" total="6" passed="3">
  <reporter-output>
  </reporter-output>
  <suite name="Default suite" duration-ms="153537" started-at="2020-12-31T00:36:46Z" finished-at="2020-12-31T00:39:19Z">
    <groups>
    </groups>
    <test name="Default test" duration-ms="153537" started-at="2020-12-31T00:36:46Z" finished-at="2020-12-31T00:39:19Z">
      <class name="Testes.BasePage">
        <test-method status="PASS" signature="open()[pri:0, instance:Testes.BasePage@204f30ec]" name="open" is-config="true" duration-ms="40846" started-at="2020-12-31T00:36:46Z" finished-at="2020-12-31T00:37:26Z">
          <reporter-output>
          </reporter-output>
        </test-method> <!-- open -->
        <test-method status="PASS" signature="FillForm()[pri:0, instance:Testes.BasePage@204f30ec]" name="FillForm" duration-ms="5000" started-at="2020-12-31T00:37:26Z" finished-at="2020-12-31T00:37:31Z">
          <reporter-output>
          </reporter-output>
        </test-method> <!-- FillForm -->
        <test-method status="PASS" signature="CloseBrowser()[pri:0, instance:Testes.BasePage@204f30ec]" name="CloseBrowser" is-config="true" duration-ms="795" started-at="2020-12-31T00:37:31Z" finished-at="2020-12-31T00:37:32Z">
          <reporter-output>
          </reporter-output>
        </test-method> <!-- CloseBrowser -->
        <test-method status="PASS" signature="open()[pri:0, instance:Testes.BasePage@204f30ec]" name="open" is-config="true" duration-ms="12402" started-at="2020-12-31T00:37:32Z" finished-at="2020-12-31T00:37:45Z">
          <reporter-output>
          </reporter-output>
        </test-method> <!-- open -->
        <test-method status="FAIL" signature="Hard_assertion()[pri:0, instance:Testes.BasePage@204f30ec]" name="Hard_assertion" duration-ms="230" started-at="2020-12-31T00:37:45Z" finished-at="2020-12-31T00:37:45Z">
          <exception class="java.lang.AssertionError">
            <message>
              <![CDATA[expected [true] but found [false]]]>
            </message>
            <full-stacktrace>
              <![CDATA[java.lang.AssertionError: expected [true] but found [false]
at org.testng.Assert.fail(Assert.java:96)
at org.testng.Assert.failNotEquals(Assert.java:776)
at org.testng.Assert.assertEqualsImpl(Assert.java:137)
at org.testng.Assert.assertEquals(Assert.java:118)
at org.testng.Assert.assertEquals(Assert.java:568)
at org.testng.Assert.assertEquals(Assert.java:578)
at Testes.BasePage.Hard_assertion(BasePage.java:123)
at sun.reflect.NativeMethodAccessorImpl.invoke0(Native Method)
at sun.reflect.NativeMethodAccessorImpl.invoke(Unknown Source)
at sun.reflect.DelegatingMethodAccessorImpl.invoke(Unknown Source)
at java.lang.reflect.Method.invoke(Unknown Source)
at org.testng.internal.MethodInvocationHelper.invokeMethod(MethodInvocationHelper.java:124)
at org.testng.internal.Invoker.invokeMethod(Invoker.java:583)
at org.testng.internal.Invoker.invokeTestMethod(Invoker.java:719)
at org.testng.internal.Invoker.invokeTestMethods(Invoker.java:989)
at org.testng.internal.TestMethodWorker.invokeTestMethods(TestMethodWorker.java:125)
at org.testng.internal.TestMethodWorker.run(TestMethodWorker.java:109)
at org.testng.TestRunner.privateRun(TestRunner.java:648)
at org.testng.TestRunner.run(TestRunner.java:505)
at org.testng.SuiteRunner.runTest(SuiteRunner.java:455)
at org.testng.SuiteRunner.runSequentially(SuiteRunner.java:450)
at org.testng.SuiteRunner.privateRun(SuiteRunner.java:415)
at org.testng.SuiteRunner.run(SuiteRunner.java:364)
at org.testng.SuiteRunnerWorker.runSuite(SuiteRunnerWorker.java:52)
at org.testng.SuiteRunnerWorker.run(SuiteRunnerWorker.java:84)
at org.testng.TestNG.runSuitesSequentially(TestNG.java:1208)
at org.testng.TestNG.runSuitesLocally(TestNG.java:1137)
at org.testng.TestNG.runSuites(TestNG.java:1049)
at org.testng.TestNG.run(TestNG.java:1017)
at org.testng.remote.AbstractRemoteTestNG.run(AbstractRemoteTestNG.java:114)
at org.testng.remote.RemoteTestNG.initAndRun(RemoteTestNG.java:251)
at org.testng.remote.RemoteTestNG.main(RemoteTestNG.java:77)
]]>
            </full-stacktrace>
          </exception> <!-- java.lang.AssertionError -->
          <reporter-output>
          </reporter-output>
        </test-method> <!-- Hard_assertion -->
        <test-method status="PASS" signature="CloseBrowser()[pri:0, instance:Testes.BasePage@204f30ec]" name="CloseBrowser" is-config="true" duration-ms="740" started-at="2020-12-31T00:37:45Z" finished-at="2020-12-31T00:37:46Z">
          <reporter-output>
          </reporter-output>
        </test-method> <!-- CloseBrowser -->
        <test-method status="PASS" signature="open()[pri:0, instance:Testes.BasePage@204f30ec]" name="open" is-config="true" duration-ms="12355" started-at="2020-12-31T00:37:46Z" finished-at="2020-12-31T00:37:58Z">
          <reporter-output>
          </reporter-output>
        </test-method> <!-- open -->
        <test-method status="PASS" signature="Sort_assertion()[pri:0, instance:Testes.BasePage@204f30ec]" name="Sort_assertion" duration-ms="1090" started-at="2020-12-31T00:37:58Z" finished-at="2020-12-31T00:37:59Z">
          <reporter-output>
          </reporter-output>
        </test-method> <!-- Sort_assertion -->
        <test-method status="PASS" signature="CloseBrowser()[pri:0, instance:Testes.BasePage@204f30ec]" name="CloseBrowser" is-config="true" duration-ms="977" started-at="2020-12-31T00:37:59Z" finished-at="2020-12-31T00:38:00Z">
          <reporter-output>
          </reporter-output>
        </test-method> <!-- CloseBrowser -->
        <test-method status="PASS" signature="open()[pri:0, instance:Testes.BasePage@204f30ec]" name="open" is-config="true" duration-ms="20846" started-at="2020-12-31T00:38:00Z" finished-at="2020-12-31T00:38:21Z">
          <reporter-output>
          </reporter-output>
        </test-method> <!-- open -->
        <test-method status="PASS" signature="Submit_Form_Label()[pri:0, instance:Testes.BasePage@204f30ec]" name="Submit_Form_Label" duration-ms="1930" started-at="2020-12-31T00:38:21Z" finished-at="2020-12-31T00:38:23Z">
          <reporter-output>
          </reporter-output>
        </test-method> <!-- Submit_Form_Label -->
        <test-method status="PASS" signature="CloseBrowser()[pri:0, instance:Testes.BasePage@204f30ec]" name="CloseBrowser" is-config="true" duration-ms="756" started-at="2020-12-31T00:38:23Z" finished-at="2020-12-31T00:38:24Z">
          <reporter-output>
          </reporter-output>
        </test-method> <!-- CloseBrowser -->
        <test-method status="PASS" signature="open()[pri:0, instance:Testes.BasePage@204f30ec]" name="open" is-config="true" duration-ms="31221" started-at="2020-12-31T00:38:24Z" finished-at="2020-12-31T00:38:55Z">
          <reporter-output>
          </reporter-output>
        </test-method> <!-- open -->
        <test-method status="FAIL" signature="verifyDB()[pri:0, instance:Testes.BasePage@204f30ec]" name="verifyDB" duration-ms="10558" started-at="2020-12-31T00:38:55Z" finished-at="2020-12-31T00:39:05Z">
          <exception class="com.mysql.cj.jdbc.exceptions.CommunicationsException">
            <message>
              <![CDATA[Communications link failure

The last packet sent successfully to the server was 0 milliseconds ago. The driver has not received any packets from the server.]]>
            </message>
            <full-stacktrace>
              <![CDATA[com.mysql.cj.jdbc.exceptions.CommunicationsException: Communications link failure

The last packet sent successfully to the server was 0 milliseconds ago. The driver has not received any packets from the server.
at com.mysql.cj.jdbc.exceptions.SQLError.createCommunicationsException(SQLError.java:174)
at com.mysql.cj.jdbc.exceptions.SQLExceptionsMapping.translateException(SQLExceptionsMapping.java:64)
at com.mysql.cj.jdbc.ConnectionImpl.createNewIO(ConnectionImpl.java:836)
at com.mysql.cj.jdbc.ConnectionImpl.<init>(ConnectionImpl.java:456)
at com.mysql.cj.jdbc.ConnectionImpl.getInstance(ConnectionImpl.java:246)
at com.mysql.cj.jdbc.NonRegisteringDriver.connect(NonRegisteringDriver.java:198)
at java.sql.DriverManager.getConnection(Unknown Source)
at java.sql.DriverManager.getConnection(Unknown Source)
at Testes.BasePage.verifyDB(BasePage.java:187)
at sun.reflect.NativeMethodAccessorImpl.invoke0(Native Method)
at sun.reflect.NativeMethodAccessorImpl.invoke(Unknown Source)
at sun.reflect.DelegatingMethodAccessorImpl.invoke(Unknown Source)
at java.lang.reflect.Method.invoke(Unknown Source)
at org.testng.internal.MethodInvocationHelper.invokeMethod(MethodInvocationHelper.java:124)
at org.testng.internal.Invoker.invokeMethod(Invoker.java:583)
at org.testng.internal.Invoker.invokeTestMethod(Invoker.java:719)
at org.testng.internal.Invoker.invokeTestMethods(Invoker.java:989)
at org.testng.internal.TestMethodWorker.invokeTestMethods(TestMethodWorker.java:125)
at org.testng.internal.TestMethodWorker.run(TestMethodWorker.java:109)
at org.testng.TestRunner.privateRun(TestRunner.java:648)
at org.testng.TestRunner.run(TestRunner.java:505)
at org.testng.SuiteRunner.runTest(SuiteRunner.java:455)
at org.testng.SuiteRunner.runSequentially(SuiteRunner.java:450)
at org.testng.SuiteRunner.privateRun(SuiteRunner.java:415)
at org.testng.SuiteRunner.run(SuiteRunner.java:364)
at org.testng.SuiteRunnerWorker.runSuite(SuiteRunnerWorker.java:52)
at org.testng.SuiteRunnerWorker.run(SuiteRunnerWorker.java:84)
at org.testng.TestNG.runSuitesSequentially(TestNG.java:1208)
at org.testng.TestNG.runSuitesLocally(TestNG.java:1137)
at org.testng.TestNG.runSuites(TestNG.java:1049)
at org.testng.TestNG.run(TestNG.java:1017)
at org.testng.remote.AbstractRemoteTestNG.run(AbstractRemoteTestNG.java:114)
at org.testng.remote.RemoteTestNG.initAndRun(RemoteTestNG.java:251)
at org.testng.remote.RemoteTestNG.main(RemoteTestNG.java:77)
Caused by: com.mysql.cj.exceptions.CJCommunicationsException: Communications link failure

The last packet sent successfully to the server was 0 milliseconds ago. The driver has not received any packets from the server.
at sun.reflect.NativeConstructorAccessorImpl.newInstance0(Native Method)
at sun.reflect.NativeConstructorAccessorImpl.newInstance(Unknown Source)
at sun.reflect.DelegatingConstructorAccessorImpl.newInstance(Unknown Source)
at java.lang.reflect.Constructor.newInstance(Unknown Source)
at com.mysql.cj.exceptions.ExceptionFactory.createException(ExceptionFactory.java:61)
at com.mysql.cj.exceptions.ExceptionFactory.createException(ExceptionFactory.java:105)
at com.mysql.cj.exceptions.ExceptionFactory.createException(ExceptionFactory.java:151)
at com.mysql.cj.exceptions.ExceptionFactory.createCommunicationsException(ExceptionFactory.java:167)
at com.mysql.cj.protocol.a.NativeSocketConnection.connect(NativeSocketConnection.java:89)
at com.mysql.cj.NativeSession.connect(NativeSession.java:144)
at com.mysql.cj.jdbc.ConnectionImpl.connectOneTryOnly(ConnectionImpl.java:956)
at com.mysql.cj.jdbc.ConnectionImpl.createNewIO(ConnectionImpl.java:826)
... 31 more
Caused by: java.net.ConnectException: Connection refused: connect
at java.net.DualStackPlainSocketImpl.connect0(Native Method)
at java.net.DualStackPlainSocketImpl.socketConnect(Unknown Source)
at java.net.AbstractPlainSocketImpl.doConnect(Unknown Source)
at java.net.AbstractPlainSocketImpl.connectToAddress(Unknown Source)
at java.net.AbstractPlainSocketImpl.connect(Unknown Source)
at java.net.PlainSocketImpl.connect(Unknown Source)
at java.net.SocksSocketImpl.connect(Unknown Source)
at java.net.Socket.connect(Unknown Source)
at com.mysql.cj.protocol.StandardSocketFactory.connect(StandardSocketFactory.java:155)
at com.mysql.cj.protocol.a.NativeSocketConnection.connect(NativeSocketConnection.java:63)
... 34 more
]]>
            </full-stacktrace>
          </exception> <!-- com.mysql.cj.jdbc.exceptions.CommunicationsException -->
          <reporter-output>
          </reporter-output>
        </test-method> <!-- verifyDB -->
        <test-method status="PASS" signature="CloseBrowser()[pri:0, instance:Testes.BasePage@204f30ec]" name="CloseBrowser" is-config="true" duration-ms="1582" started-at="2020-12-31T00:39:05Z" finished-at="2020-12-31T00:39:07Z">
          <reporter-output>
          </reporter-output>
        </test-method> <!-- CloseBrowser -->
        <test-method status="PASS" signature="open()[pri:0, instance:Testes.BasePage@204f30ec]" name="open" is-config="true" duration-ms="9271" started-at="2020-12-31T00:39:07Z" finished-at="2020-12-31T00:39:16Z">
          <reporter-output>
          </reporter-output>
        </test-method> <!-- open -->
        <test-method status="FAIL" signature="verifyemailTriggered()[pri:0, instance:Testes.BasePage@204f30ec]" name="verifyemailTriggered" duration-ms="2034" started-at="2020-12-31T00:39:16Z" finished-at="2020-12-31T00:39:18Z">
          <exception class="com.mysql.cj.jdbc.exceptions.CommunicationsException">
            <message>
              <![CDATA[Communications link failure

The last packet sent successfully to the server was 0 milliseconds ago. The driver has not received any packets from the server.]]>
            </message>
            <full-stacktrace>
              <![CDATA[com.mysql.cj.jdbc.exceptions.CommunicationsException: Communications link failure

The last packet sent successfully to the server was 0 milliseconds ago. The driver has not received any packets from the server.
at com.mysql.cj.jdbc.exceptions.SQLError.createCommunicationsException(SQLError.java:174)
at com.mysql.cj.jdbc.exceptions.SQLExceptionsMapping.translateException(SQLExceptionsMapping.java:64)
at com.mysql.cj.jdbc.ConnectionImpl.createNewIO(ConnectionImpl.java:836)
at com.mysql.cj.jdbc.ConnectionImpl.<init>(ConnectionImpl.java:456)
at com.mysql.cj.jdbc.ConnectionImpl.getInstance(ConnectionImpl.java:246)
at com.mysql.cj.jdbc.NonRegisteringDriver.connect(NonRegisteringDriver.java:198)
at java.sql.DriverManager.getConnection(Unknown Source)
at java.sql.DriverManager.getConnection(Unknown Source)
at Testes.BasePage.verifyemailTriggered(BasePage.java:232)
at sun.reflect.NativeMethodAccessorImpl.invoke0(Native Method)
at sun.reflect.NativeMethodAccessorImpl.invoke(Unknown Source)
at sun.reflect.DelegatingMethodAccessorImpl.invoke(Unknown Source)
at java.lang.reflect.Method.invoke(Unknown Source)
at org.testng.internal.MethodInvocationHelper.invokeMethod(MethodInvocationHelper.java:124)
at org.testng.internal.Invoker.invokeMethod(Invoker.java:583)
at org.testng.internal.Invoker.invokeTestMethod(Invoker.java:719)
at org.testng.internal.Invoker.invokeTestMethods(Invoker.java:989)
at org.testng.internal.TestMethodWorker.invokeTestMethods(TestMethodWorker.java:125)
at org.testng.internal.TestMethodWorker.run(TestMethodWorker.java:109)
at org.testng.TestRunner.privateRun(TestRunner.java:648)
at org.testng.TestRunner.run(TestRunner.java:505)
at org.testng.SuiteRunner.runTest(SuiteRunner.java:455)
at org.testng.SuiteRunner.runSequentially(SuiteRunner.java:450)
at org.testng.SuiteRunner.privateRun(SuiteRunner.java:415)
at org.testng.SuiteRunner.run(SuiteRunner.java:364)
at org.testng.SuiteRunnerWorker.runSuite(SuiteRunnerWorker.java:52)
at org.testng.SuiteRunnerWorker.run(SuiteRunnerWorker.java:84)
at org.testng.TestNG.runSuitesSequentially(TestNG.java:1208)
at org.testng.TestNG.runSuitesLocally(TestNG.java:1137)
at org.testng.TestNG.runSuites(TestNG.java:1049)
at org.testng.TestNG.run(TestNG.java:1017)
at org.testng.remote.AbstractRemoteTestNG.run(AbstractRemoteTestNG.java:114)
at org.testng.remote.RemoteTestNG.initAndRun(RemoteTestNG.java:251)
at org.testng.remote.RemoteTestNG.main(RemoteTestNG.java:77)
Caused by: com.mysql.cj.exceptions.CJCommunicationsException: Communications link failure

The last packet sent successfully to the server was 0 milliseconds ago. The driver has not received any packets from the server.
at sun.reflect.NativeConstructorAccessorImpl.newInstance0(Native Method)
at sun.reflect.NativeConstructorAccessorImpl.newInstance(Unknown Source)
at sun.reflect.DelegatingConstructorAccessorImpl.newInstance(Unknown Source)
at java.lang.reflect.Constructor.newInstance(Unknown Source)
at com.mysql.cj.exceptions.ExceptionFactory.createException(ExceptionFactory.java:61)
at com.mysql.cj.exceptions.ExceptionFactory.createException(ExceptionFactory.java:105)
at com.mysql.cj.exceptions.ExceptionFactory.createException(ExceptionFactory.java:151)
at com.mysql.cj.exceptions.ExceptionFactory.createCommunicationsException(ExceptionFactory.java:167)
at com.mysql.cj.protocol.a.NativeSocketConnection.connect(NativeSocketConnection.java:89)
at com.mysql.cj.NativeSession.connect(NativeSession.java:144)
at com.mysql.cj.jdbc.ConnectionImpl.connectOneTryOnly(ConnectionImpl.java:956)
at com.mysql.cj.jdbc.ConnectionImpl.createNewIO(ConnectionImpl.java:826)
... 31 more
Caused by: java.net.ConnectException: Connection refused: connect
at java.net.DualStackPlainSocketImpl.connect0(Native Method)
at java.net.DualStackPlainSocketImpl.socketConnect(Unknown Source)
at java.net.AbstractPlainSocketImpl.doConnect(Unknown Source)
at java.net.AbstractPlainSocketImpl.connectToAddress(Unknown Source)
at java.net.AbstractPlainSocketImpl.connect(Unknown Source)
at java.net.PlainSocketImpl.connect(Unknown Source)
at java.net.SocksSocketImpl.connect(Unknown Source)
at java.net.Socket.connect(Unknown Source)
at com.mysql.cj.protocol.StandardSocketFactory.connect(StandardSocketFactory.java:155)
at com.mysql.cj.protocol.a.NativeSocketConnection.connect(NativeSocketConnection.java:63)
... 34 more
]]>
            </full-stacktrace>
          </exception> <!-- com.mysql.cj.jdbc.exceptions.CommunicationsException -->
          <reporter-output>
          </reporter-output>
        </test-method> <!-- verifyemailTriggered -->
        <test-method status="PASS" signature="CloseBrowser()[pri:0, instance:Testes.BasePage@204f30ec]" name="CloseBrowser" is-config="true" duration-ms="832" started-at="2020-12-31T00:39:18Z" finished-at="2020-12-31T00:39:19Z">
          <reporter-output>
          </reporter-output>
        </test-method> <!-- CloseBrowser -->
      </class> <!-- Testes.BasePage -->
    </test> <!-- Default test -->
  </suite> <!-- Default suite -->
</testng-results>
