<?xml version="1.0" encoding="UTF-8"?>
<testng-results skipped="0" failed="3" ignored="0" total="6" passed="3">
  <reporter-output>
  </reporter-output>
  <suite name="Default suite" duration-ms="93687" started-at="2020-12-31T00:12:38Z" finished-at="2020-12-31T00:14:12Z">
    <groups>
    </groups>
    <test name="Default test" duration-ms="93687" started-at="2020-12-31T00:12:38Z" finished-at="2020-12-31T00:14:12Z">
      <class name="Pages.BasePage">
        <test-method status="PASS" signature="open()[pri:0, instance:Pages.BasePage@204f30ec]" name="open" is-config="true" duration-ms="13251" started-at="2020-12-31T00:12:38Z" finished-at="2020-12-31T00:12:52Z">
          <reporter-output>
          </reporter-output>
        </test-method> <!-- open -->
        <test-method status="PASS" signature="FillForm()[pri:0, instance:Pages.BasePage@204f30ec]" name="FillForm" duration-ms="6252" started-at="2020-12-31T00:12:52Z" finished-at="2020-12-31T00:12:58Z">
          <reporter-output>
          </reporter-output>
        </test-method> <!-- FillForm -->
        <test-method status="PASS" signature="CloseBrowser()[pri:0, instance:Pages.BasePage@204f30ec]" name="CloseBrowser" is-config="true" duration-ms="2435" started-at="2020-12-31T00:12:58Z" finished-at="2020-12-31T00:13:00Z">
          <reporter-output>
          </reporter-output>
        </test-method> <!-- CloseBrowser -->
        <test-method status="PASS" signature="open()[pri:0, instance:Pages.BasePage@204f30ec]" name="open" is-config="true" duration-ms="14234" started-at="2020-12-31T00:13:00Z" finished-at="2020-12-31T00:13:15Z">
          <reporter-output>
          </reporter-output>
        </test-method> <!-- open -->
        <test-method status="FAIL" signature="Hard_assertion()[pri:0, instance:Pages.BasePage@204f30ec]" name="Hard_assertion" duration-ms="150" started-at="2020-12-31T00:13:15Z" finished-at="2020-12-31T00:13:15Z">
          <exception class="java.lang.AssertionError">
            <message>
              <![CDATA[expected [true] but found [false]]]>
            </message>
            <full-stacktrace>
              <![CDATA[java.lang.AssertionError: expected [true] but found [false]
at org.testng.Assert.fail(Assert.java:96)
at org.testng.Assert.failNotEquals(Assert.java:776)
at org.testng.Assert.assertEqualsImpl(Assert.java:137)
at org.testng.Assert.assertEquals(Assert.java:118)
at org.testng.Assert.assertEquals(Assert.java:568)
at org.testng.Assert.assertEquals(Assert.java:578)
at Pages.BasePage.Hard_assertion(BasePage.java:123)
at sun.reflect.NativeMethodAccessorImpl.invoke0(Native Method)
at sun.reflect.NativeMethodAccessorImpl.invoke(Unknown Source)
at sun.reflect.DelegatingMethodAccessorImpl.invoke(Unknown Source)
at java.lang.reflect.Method.invoke(Unknown Source)
at org.testng.internal.MethodInvocationHelper.invokeMethod(MethodInvocationHelper.java:124)
at org.testng.internal.Invoker.invokeMethod(Invoker.java:583)
at org.testng.internal.Invoker.invokeTestMethod(Invoker.java:719)
at org.testng.internal.Invoker.invokeTestMethods(Invoker.java:989)
at org.testng.internal.TestMethodWorker.invokeTestMethods(TestMethodWorker.java:125)
at org.testng.internal.TestMethodWorker.run(TestMethodWorker.java:109)
at org.testng.TestRunner.privateRun(TestRunner.java:648)
at org.testng.TestRunner.run(TestRunner.java:505)
at org.testng.SuiteRunner.runTest(SuiteRunner.java:455)
at org.testng.SuiteRunner.runSequentially(SuiteRunner.java:450)
at org.testng.SuiteRunner.privateRun(SuiteRunner.java:415)
at org.testng.SuiteRunner.run(SuiteRunner.java:364)
at org.testng.SuiteRunnerWorker.runSuite(SuiteRunnerWorker.java:52)
at org.testng.SuiteRunnerWorker.run(SuiteRunnerWorker.java:84)
at org.testng.TestNG.runSuitesSequentially(TestNG.java:1208)
at org.testng.TestNG.runSuitesLocally(TestNG.java:1137)
at org.testng.TestNG.runSuites(TestNG.java:1049)
at org.testng.TestNG.run(TestNG.java:1017)
at org.testng.remote.AbstractRemoteTestNG.run(AbstractRemoteTestNG.java:114)
at org.testng.remote.RemoteTestNG.initAndRun(RemoteTestNG.java:251)
at org.testng.remote.RemoteTestNG.main(RemoteTestNG.java:77)
]]>
            </full-stacktrace>
          </exception> <!-- java.lang.AssertionError -->
          <reporter-output>
          </reporter-output>
        </test-method> <!-- Hard_assertion -->
        <test-method status="PASS" signature="CloseBrowser()[pri:0, instance:Pages.BasePage@204f30ec]" name="CloseBrowser" is-config="true" duration-ms="848" started-at="2020-12-31T00:13:15Z" finished-at="2020-12-31T00:13:16Z">
          <reporter-output>
          </reporter-output>
        </test-method> <!-- CloseBrowser -->
        <test-method status="PASS" signature="open()[pri:0, instance:Pages.BasePage@204f30ec]" name="open" is-config="true" duration-ms="12184" started-at="2020-12-31T00:13:16Z" finished-at="2020-12-31T00:13:28Z">
          <reporter-output>
          </reporter-output>
        </test-method> <!-- open -->
        <test-method status="PASS" signature="Sort_assertion()[pri:0, instance:Pages.BasePage@204f30ec]" name="Sort_assertion" duration-ms="625" started-at="2020-12-31T00:13:28Z" finished-at="2020-12-31T00:13:28Z">
          <reporter-output>
          </reporter-output>
        </test-method> <!-- Sort_assertion -->
        <test-method status="PASS" signature="CloseBrowser()[pri:0, instance:Pages.BasePage@204f30ec]" name="CloseBrowser" is-config="true" duration-ms="830" started-at="2020-12-31T00:13:28Z" finished-at="2020-12-31T00:13:29Z">
          <reporter-output>
          </reporter-output>
        </test-method> <!-- CloseBrowser -->
        <test-method status="PASS" signature="open()[pri:0, instance:Pages.BasePage@204f30ec]" name="open" is-config="true" duration-ms="11715" started-at="2020-12-31T00:13:29Z" finished-at="2020-12-31T00:13:41Z">
          <reporter-output>
          </reporter-output>
        </test-method> <!-- open -->
        <test-method status="PASS" signature="Submit_Form_Label()[pri:0, instance:Pages.BasePage@204f30ec]" name="Submit_Form_Label" duration-ms="835" started-at="2020-12-31T00:13:41Z" finished-at="2020-12-31T00:13:42Z">
          <reporter-output>
          </reporter-output>
        </test-method> <!-- Submit_Form_Label -->
        <test-method status="PASS" signature="CloseBrowser()[pri:0, instance:Pages.BasePage@204f30ec]" name="CloseBrowser" is-config="true" duration-ms="1249" started-at="2020-12-31T00:13:42Z" finished-at="2020-12-31T00:13:43Z">
          <reporter-output>
          </reporter-output>
        </test-method> <!-- CloseBrowser -->
        <test-method status="PASS" signature="open()[pri:0, instance:Pages.BasePage@204f30ec]" name="open" is-config="true" duration-ms="11255" started-at="2020-12-31T00:13:43Z" finished-at="2020-12-31T00:13:54Z">
          <reporter-output>
          </reporter-output>
        </test-method> <!-- open -->
        <test-method status="FAIL" signature="verifyDB()[pri:0, instance:Pages.BasePage@204f30ec]" name="verifyDB" duration-ms="2311" started-at="2020-12-31T00:13:54Z" finished-at="2020-12-31T00:13:57Z">
          <exception class="com.mysql.cj.jdbc.exceptions.CommunicationsException">
            <message>
              <![CDATA[Communications link failure

The last packet sent successfully to the server was 0 milliseconds ago. The driver has not received any packets from the server.]]>
            </message>
            <full-stacktrace>
              <![CDATA[com.mysql.cj.jdbc.exceptions.CommunicationsException: Communications link failure

The last packet sent successfully to the server was 0 milliseconds ago. The driver has not received any packets from the server.
at com.mysql.cj.jdbc.exceptions.SQLError.createCommunicationsException(SQLError.java:174)
at com.mysql.cj.jdbc.exceptions.SQLExceptionsMapping.translateException(SQLExceptionsMapping.java:64)
at com.mysql.cj.jdbc.ConnectionImpl.createNewIO(ConnectionImpl.java:836)
at com.mysql.cj.jdbc.ConnectionImpl.<init>(ConnectionImpl.java:456)
at com.mysql.cj.jdbc.ConnectionImpl.getInstance(ConnectionImpl.java:246)
at com.mysql.cj.jdbc.NonRegisteringDriver.connect(NonRegisteringDriver.java:198)
at java.sql.DriverManager.getConnection(Unknown Source)
at java.sql.DriverManager.getConnection(Unknown Source)
at Pages.BasePage.verifyDB(BasePage.java:187)
at sun.reflect.NativeMethodAccessorImpl.invoke0(Native Method)
at sun.reflect.NativeMethodAccessorImpl.invoke(Unknown Source)
at sun.reflect.DelegatingMethodAccessorImpl.invoke(Unknown Source)
at java.lang.reflect.Method.invoke(Unknown Source)
at org.testng.internal.MethodInvocationHelper.invokeMethod(MethodInvocationHelper.java:124)
at org.testng.internal.Invoker.invokeMethod(Invoker.java:583)
at org.testng.internal.Invoker.invokeTestMethod(Invoker.java:719)
at org.testng.internal.Invoker.invokeTestMethods(Invoker.java:989)
at org.testng.internal.TestMethodWorker.invokeTestMethods(TestMethodWorker.java:125)
at org.testng.internal.TestMethodWorker.run(TestMethodWorker.java:109)
at org.testng.TestRunner.privateRun(TestRunner.java:648)
at org.testng.TestRunner.run(TestRunner.java:505)
at org.testng.SuiteRunner.runTest(SuiteRunner.java:455)
at org.testng.SuiteRunner.runSequentially(SuiteRunner.java:450)
at org.testng.SuiteRunner.privateRun(SuiteRunner.java:415)
at org.testng.SuiteRunner.run(SuiteRunner.java:364)
at org.testng.SuiteRunnerWorker.runSuite(SuiteRunnerWorker.java:52)
at org.testng.SuiteRunnerWorker.run(SuiteRunnerWorker.java:84)
at org.testng.TestNG.runSuitesSequentially(TestNG.java:1208)
at org.testng.TestNG.runSuitesLocally(TestNG.java:1137)
at org.testng.TestNG.runSuites(TestNG.java:1049)
at org.testng.TestNG.run(TestNG.java:1017)
at org.testng.remote.AbstractRemoteTestNG.run(AbstractRemoteTestNG.java:114)
at org.testng.remote.RemoteTestNG.initAndRun(RemoteTestNG.java:251)
at org.testng.remote.RemoteTestNG.main(RemoteTestNG.java:77)
Caused by: com.mysql.cj.exceptions.CJCommunicationsException: Communications link failure

The last packet sent successfully to the server was 0 milliseconds ago. The driver has not received any packets from the server.
at sun.reflect.NativeConstructorAccessorImpl.newInstance0(Native Method)
at sun.reflect.NativeConstructorAccessorImpl.newInstance(Unknown Source)
at sun.reflect.DelegatingConstructorAccessorImpl.newInstance(Unknown Source)
at java.lang.reflect.Constructor.newInstance(Unknown Source)
at com.mysql.cj.exceptions.ExceptionFactory.createException(ExceptionFactory.java:61)
at com.mysql.cj.exceptions.ExceptionFactory.createException(ExceptionFactory.java:105)
at com.mysql.cj.exceptions.ExceptionFactory.createException(ExceptionFactory.java:151)
at com.mysql.cj.exceptions.ExceptionFactory.createCommunicationsException(ExceptionFactory.java:167)
at com.mysql.cj.protocol.a.NativeSocketConnection.connect(NativeSocketConnection.java:89)
at com.mysql.cj.NativeSession.connect(NativeSession.java:144)
at com.mysql.cj.jdbc.ConnectionImpl.connectOneTryOnly(ConnectionImpl.java:956)
at com.mysql.cj.jdbc.ConnectionImpl.createNewIO(ConnectionImpl.java:826)
... 31 more
Caused by: java.net.ConnectException: Connection refused: connect
at java.net.DualStackPlainSocketImpl.connect0(Native Method)
at java.net.DualStackPlainSocketImpl.socketConnect(Unknown Source)
at java.net.AbstractPlainSocketImpl.doConnect(Unknown Source)
at java.net.AbstractPlainSocketImpl.connectToAddress(Unknown Source)
at java.net.AbstractPlainSocketImpl.connect(Unknown Source)
at java.net.PlainSocketImpl.connect(Unknown Source)
at java.net.SocksSocketImpl.connect(Unknown Source)
at java.net.Socket.connect(Unknown Source)
at com.mysql.cj.protocol.StandardSocketFactory.connect(StandardSocketFactory.java:155)
at com.mysql.cj.protocol.a.NativeSocketConnection.connect(NativeSocketConnection.java:63)
... 34 more
]]>
            </full-stacktrace>
          </exception> <!-- com.mysql.cj.jdbc.exceptions.CommunicationsException -->
          <reporter-output>
          </reporter-output>
        </test-method> <!-- verifyDB -->
        <test-method status="PASS" signature="CloseBrowser()[pri:0, instance:Pages.BasePage@204f30ec]" name="CloseBrowser" is-config="true" duration-ms="826" started-at="2020-12-31T00:13:57Z" finished-at="2020-12-31T00:13:57Z">
          <reporter-output>
          </reporter-output>
        </test-method> <!-- CloseBrowser -->
        <test-method status="PASS" signature="open()[pri:0, instance:Pages.BasePage@204f30ec]" name="open" is-config="true" duration-ms="11702" started-at="2020-12-31T00:13:57Z" finished-at="2020-12-31T00:14:09Z">
          <reporter-output>
          </reporter-output>
        </test-method> <!-- open -->
        <test-method status="FAIL" signature="verifyemailTriggered()[pri:0, instance:Pages.BasePage@204f30ec]" name="verifyemailTriggered" duration-ms="2006" started-at="2020-12-31T00:14:09Z" finished-at="2020-12-31T00:14:11Z">
          <exception class="com.mysql.cj.jdbc.exceptions.CommunicationsException">
            <message>
              <![CDATA[Communications link failure

The last packet sent successfully to the server was 0 milliseconds ago. The driver has not received any packets from the server.]]>
            </message>
            <full-stacktrace>
              <![CDATA[com.mysql.cj.jdbc.exceptions.CommunicationsException: Communications link failure

The last packet sent successfully to the server was 0 milliseconds ago. The driver has not received any packets from the server.
at com.mysql.cj.jdbc.exceptions.SQLError.createCommunicationsException(SQLError.java:174)
at com.mysql.cj.jdbc.exceptions.SQLExceptionsMapping.translateException(SQLExceptionsMapping.java:64)
at com.mysql.cj.jdbc.ConnectionImpl.createNewIO(ConnectionImpl.java:836)
at com.mysql.cj.jdbc.ConnectionImpl.<init>(ConnectionImpl.java:456)
at com.mysql.cj.jdbc.ConnectionImpl.getInstance(ConnectionImpl.java:246)
at com.mysql.cj.jdbc.NonRegisteringDriver.connect(NonRegisteringDriver.java:198)
at java.sql.DriverManager.getConnection(Unknown Source)
at java.sql.DriverManager.getConnection(Unknown Source)
at Pages.BasePage.verifyemailTriggered(BasePage.java:232)
at sun.reflect.NativeMethodAccessorImpl.invoke0(Native Method)
at sun.reflect.NativeMethodAccessorImpl.invoke(Unknown Source)
at sun.reflect.DelegatingMethodAccessorImpl.invoke(Unknown Source)
at java.lang.reflect.Method.invoke(Unknown Source)
at org.testng.internal.MethodInvocationHelper.invokeMethod(MethodInvocationHelper.java:124)
at org.testng.internal.Invoker.invokeMethod(Invoker.java:583)
at org.testng.internal.Invoker.invokeTestMethod(Invoker.java:719)
at org.testng.internal.Invoker.invokeTestMethods(Invoker.java:989)
at org.testng.internal.TestMethodWorker.invokeTestMethods(TestMethodWorker.java:125)
at org.testng.internal.TestMethodWorker.run(TestMethodWorker.java:109)
at org.testng.TestRunner.privateRun(TestRunner.java:648)
at org.testng.TestRunner.run(TestRunner.java:505)
at org.testng.SuiteRunner.runTest(SuiteRunner.java:455)
at org.testng.SuiteRunner.runSequentially(SuiteRunner.java:450)
at org.testng.SuiteRunner.privateRun(SuiteRunner.java:415)
at org.testng.SuiteRunner.run(SuiteRunner.java:364)
at org.testng.SuiteRunnerWorker.runSuite(SuiteRunnerWorker.java:52)
at org.testng.SuiteRunnerWorker.run(SuiteRunnerWorker.java:84)
at org.testng.TestNG.runSuitesSequentially(TestNG.java:1208)
at org.testng.TestNG.runSuitesLocally(TestNG.java:1137)
at org.testng.TestNG.runSuites(TestNG.java:1049)
at org.testng.TestNG.run(TestNG.java:1017)
at org.testng.remote.AbstractRemoteTestNG.run(AbstractRemoteTestNG.java:114)
at org.testng.remote.RemoteTestNG.initAndRun(RemoteTestNG.java:251)
at org.testng.remote.RemoteTestNG.main(RemoteTestNG.java:77)
Caused by: com.mysql.cj.exceptions.CJCommunicationsException: Communications link failure

The last packet sent successfully to the server was 0 milliseconds ago. The driver has not received any packets from the server.
at sun.reflect.NativeConstructorAccessorImpl.newInstance0(Native Method)
at sun.reflect.NativeConstructorAccessorImpl.newInstance(Unknown Source)
at sun.reflect.DelegatingConstructorAccessorImpl.newInstance(Unknown Source)
at java.lang.reflect.Constructor.newInstance(Unknown Source)
at com.mysql.cj.exceptions.ExceptionFactory.createException(ExceptionFactory.java:61)
at com.mysql.cj.exceptions.ExceptionFactory.createException(ExceptionFactory.java:105)
at com.mysql.cj.exceptions.ExceptionFactory.createException(ExceptionFactory.java:151)
at com.mysql.cj.exceptions.ExceptionFactory.createCommunicationsException(ExceptionFactory.java:167)
at com.mysql.cj.protocol.a.NativeSocketConnection.connect(NativeSocketConnection.java:89)
at com.mysql.cj.NativeSession.connect(NativeSession.java:144)
at com.mysql.cj.jdbc.ConnectionImpl.connectOneTryOnly(ConnectionImpl.java:956)
at com.mysql.cj.jdbc.ConnectionImpl.createNewIO(ConnectionImpl.java:826)
... 31 more
Caused by: java.net.ConnectException: Connection refused: connect
at java.net.DualStackPlainSocketImpl.connect0(Native Method)
at java.net.DualStackPlainSocketImpl.socketConnect(Unknown Source)
at java.net.AbstractPlainSocketImpl.doConnect(Unknown Source)
at java.net.AbstractPlainSocketImpl.connectToAddress(Unknown Source)
at java.net.AbstractPlainSocketImpl.connect(Unknown Source)
at java.net.PlainSocketImpl.connect(Unknown Source)
at java.net.SocksSocketImpl.connect(Unknown Source)
at java.net.Socket.connect(Unknown Source)
at com.mysql.cj.protocol.StandardSocketFactory.connect(StandardSocketFactory.java:155)
at com.mysql.cj.protocol.a.NativeSocketConnection.connect(NativeSocketConnection.java:63)
... 34 more
]]>
            </full-stacktrace>
          </exception> <!-- com.mysql.cj.jdbc.exceptions.CommunicationsException -->
          <reporter-output>
          </reporter-output>
        </test-method> <!-- verifyemailTriggered -->
        <test-method status="PASS" signature="CloseBrowser()[pri:0, instance:Pages.BasePage@204f30ec]" name="CloseBrowser" is-config="true" duration-ms="909" started-at="2020-12-31T00:14:11Z" finished-at="2020-12-31T00:14:12Z">
          <reporter-output>
          </reporter-output>
        </test-method> <!-- CloseBrowser -->
      </class> <!-- Pages.BasePage -->
    </test> <!-- Default test -->
  </suite> <!-- Default suite -->
</testng-results>
